<?xml version="1.0" encoding="utf-8"?>
<!-- This URDF was automatically created by SolidWorks to URDF Exporter! Originally created by Stephen Brawner (brawner@gmail.com) 
     Commit Version: 1.6.0-1-g15f4949  Build Version: 1.6.7594.29634
     For more information, please see http://wiki.ros.org/sw_urdf_exporter -->
<robot
  name="FULL VEHICLE ASY_1">
  <link
    name="Chassis">
    <inertial>
      <origin
        xyz="0.573017193776333 -0.194811261558842 -0.312404680017113"
        rpy="0 0 0" />
      <mass
        value="42.3305763851261" />
      <inertia
        ixx="1.32400409003049"
        ixy="-5.47530430368531E-07"
        ixz="-0.0108533000365126"
        iyy="4.07301378956163"
        iyz="-0.0370974629602942"
        izz="3.13522701218487" />
    </inertial>
    <visual>
      <origin
        xyz="0 0 0"
        rpy="0 0 0" />
      <geometry>
        <mesh
          filename="package://FULL VEHICLE ASY_1/meshes/Chassis.STL" />
      </geometry>
      <material
        name="">
        <color
          rgba="0.752941176470588 0.752941176470588 0.752941176470588 1" />
      </material>
    </visual>
    <collision>
      <origin
        xyz="0 0 0"
        rpy="0 0 0" />
      <geometry>
        <mesh
          filename="package://FULL VEHICLE ASY_1/meshes/Chassis.STL" />
      </geometry>
    </collision>
  </link>
  <link
    name="Steering">
    <inertial>
      <origin
        xyz="-0.00219945835481239 -0.368653313466684 -0.00294571826150181"
        rpy="0 0 0" />
      <mass
        value="4.35864658175105" />
      <inertia
        ixx="0.035808504311998"
        ixy="2.86743145042425E-06"
        ixz="0.00043597663524228"
        iyy="0.0092797593941919"
        iyz="1.44196099363333E-05"
        izz="0.0405521494200921" />
    </inertial>
    <visual>
      <origin
        xyz="0 0 0"
        rpy="0 0 0" />
      <geometry>
        <mesh
          filename="package://FULL VEHICLE ASY_1/meshes/Steering.STL" />
      </geometry>
      <material
        name="">
        <color
          rgba="0.792156862745098 0.819607843137255 0.933333333333333 1" />
      </material>
    </visual>
    <collision>
      <origin
        xyz="0 0 0"
        rpy="0 0 0" />
      <geometry>
        <mesh
          filename="package://FULL VEHICLE ASY_1/meshes/Steering.STL" />
      </geometry>
    </collision>
  </link>
  <joint
    name="Steering"
    type="continuous">
    <origin
      xyz="0.5804791541301 0.0694321603143924 0.886803411953135"
      rpy="-0.141050341623528 0 0" />
    <parent
      link="Chassis" />
    <child
      link="Steering" />
    <axis
      xyz="0 -1 0" />
  </joint>
  <link
    name="Front_wheel">
    <inertial>
      <origin
        xyz="-0.0391648619324694 0.00286263655941621 0.00579793609474111"
        rpy="0 0 0" />
      <mass
        value="1.48112921953003" />
      <inertia
        ixx="0.0208248156846066"
        ixy="0.000123508914882059"
        ixz="-0.000864149184915356"
        iyy="0.0111279650903332"
        iyz="3.41600464714938E-05"
        izz="0.0111798555885646" />
    </inertial>
    <visual>
      <origin
        xyz="0 0 0"
        rpy="0 0 0" />
      <geometry>
        <mesh
          filename="package://FULL VEHICLE ASY_1/meshes/Front_wheel.STL" />
      </geometry>
      <material
        name="">
        <color
          rgba="0.792156862745098 0.819607843137255 0.933333333333333 1" />
      </material>
    </visual>
    <collision>
      <origin
        xyz="0 0 0"
        rpy="0 0 0" />
      <geometry>
        <mesh
          filename="package://FULL VEHICLE ASY_1/meshes/Front_wheel.STL" />
      </geometry>
    </collision>
  </link>
  <joint
    name="Front_wheel"
    type="continuous">
    <origin
      xyz="-0.0255963081694544 -0.697292952790359 0.0044320095770034"
      rpy="3.00054231196627 0 3.14159265358979" />
    <parent
      link="Steering" />
    <child
      link="Front_wheel" />
    <axis
      xyz="-0.996007247148133 -0.0125501927179166 0.0883858376163311" />
  </joint>
  <link
    name="Back_wheel_1">
    <inertial>
      <origin
        xyz="0.000777643244766257 -0.000887749458798659 6.08546578977354E-05"
        rpy="0 0 0" />
      <mass
        value="1.06720495669598" />
      <inertia
        ixx="0.0193062063819411"
        ixy="2.72567691181148E-06"
        ixz="7.19872612730974E-07"
        iyy="0.0102290694834791"
        iyz="-7.70595475164233E-06"
        izz="0.010137494452828" />
    </inertial>
    <visual>
      <origin
        xyz="0 0 0"
        rpy="0 0 0" />
      <geometry>
        <mesh
          filename="package://FULL VEHICLE ASY_1/meshes/Back_wheel_1.STL" />
      </geometry>
      <material
        name="">
        <color
          rgba="0.792156862745098 0.819607843137255 0.933333333333333 1" />
      </material>
    </visual>
    <collision>
      <origin
        xyz="0 0 0"
        rpy="0 0 0" />
      <geometry>
        <mesh
          filename="package://FULL VEHICLE ASY_1/meshes/Back_wheel_1.STL" />
      </geometry>
    </collision>
  </link>
  <joint
    name="Back_wheel_1"
    type="continuous">
    <origin
      xyz="1.04069481833247 -0.663239713487483 -1.35218656184676"
      rpy="3.14159265358979 0 3.14159265358979" />
    <parent
      link="Chassis" />
    <child
      link="Back_wheel_1" />
    <axis
      xyz="-1 0 0" />
  </joint>
  <link
    name="Back_wheel_2">
    <inertial>
      <origin
        xyz="0.000777643244766368 -0.000887749458798326 6.08546578981795E-05"
        rpy="0 0 0" />
      <mass
        value="1.06720495669597" />
      <inertia
        ixx="0.0193062063819408"
        ixy="2.72567691180757E-06"
        ixz="7.19872612724851E-07"
        iyy="0.010229069483479"
        iyz="-7.70595475165993E-06"
        izz="0.0101374944528278" />
    </inertial>
    <visual>
      <origin
        xyz="0 0 0"
        rpy="0 0 0" />
      <geometry>
        <mesh
          filename="package://FULL VEHICLE ASY_1/meshes/Back_wheel_2.STL" />
      </geometry>
      <material
        name="">
        <color
          rgba="0.792156862745098 0.819607843137255 0.933333333333333 1" />
      </material>
    </visual>
    <collision>
      <origin
        xyz="0 0 0"
        rpy="0 0 0" />
      <geometry>
        <mesh
          filename="package://FULL VEHICLE ASY_1/meshes/Back_wheel_2.STL" />
      </geometry>
    </collision>
  </link>
  <joint
    name="Back_wheel_2"
    type="continuous">
    <origin
      xyz="0.123294818332466 -0.663239713487483 -1.35218656184675"
      rpy="3.14159265358979 0 3.14159265358979" />
    <parent
      link="Chassis" />
    <child
      link="Back_wheel_2" />
    <axis
      xyz="-1 0 0" />
  </joint>
</robot>